Workbook

Sheet Visão
A3: Soma de M2 Vendido | B3: Rótulos de Coluna
A4: Rótulos de Linha | B4: 46142 | C4: 46153 | D4: 46154 | E4: 46155 | F4: 46157 | G4: 46161 | H4: 46162 | I4: 46163 | J4: 46164 | K4: 46151 | L4: 46156 | M4: 46160 | N4: 46168 | O4: 46158 | P4: 46159 | Q4: 46167 | R4: 46166 | S4: 46170 | T4: 46171 | U4: 46172 | V4: Total Geral
C5: 2.9664 | D5: 8.3069 | E5: 12.3931 | F5: 57.2193 | G5: 28.3774 | H5: 0.5 | I5: 2.583 | J5: 0.5396 | L5: 6.6597 | M5: 2.6391 | N5: 1.45 | O5: 4.9695 | P5: 9.544 | Q5: 0.2513 | U5: 0.64 | V5: 139.0393
A6: ESI04 | C6: 2.6565 | D6: 7.2489 | E6: 4.5387 | H6: 0.5 | I6: 1.92 | N6: 1.45 | O6: 4.9695 | P6: 9.544 | U6: 0.64 | V6: 33.4676
A7: FUM06 | F7: 13.342 | V7: 13.342
A8: FUM08 | D8: 1.058 | E8: 6.1838 | F8: 21.5456 | G8: 26.3142 | M8: 2.6391 | V8: 57.7407
A9: INC03 | F9: 0.3515 | V9: 0.3515
A10: INC08 | E10: 1.3612 | F10: 21.9802 | I10: 0.663 | L10: 6.3955 | Q10: 0.2513 | V10: 30.6512
A11: MBI03 | C11: 0.3099 | E11: 0.3094 | J11: 0.25 | L11: 0.2642 | V11: 1.1335
A12: VRD08 | G12: 2.0632 | V12: 2.0632
A13: FUM04 | J13: 0.2896 | V13: 0.2896
A14: 1P | G14: 39.6398 | N14: 169.6926 | T14: 18.0734 | V14: 227.4058
A15: INC06 | G15: 18.0257 | N15: 132.0984 | T15: 18.0734 | V15: 168.1975
A16: INC08 | G16: 15.5833 | V16: 15.5833
A17: INC10 | G17: 3.159 | V17: 3.159
A18: LMINC08 | N18: 16.6759 | V18: 16.6759
A19: LMLT06 | N19: 6.8332 | V19: 6.8332
A20: MBI03 | G20: 2.8718 | N20: 3.2608 | V20: 6.1326
A21: ESIA06 | N21: 10.8243 | V21: 10.8243
A22: 3B | C22: 3.0697 | H22: 36.6996 | M22: 56.1228 | Q22: 60.3326 | S22: 9.438 | V22: 165.6627
A23: ESI04 | H23: 3.3926 | V23: 3.3926
A24: INC06 | H24: 25.5776 | M24: 29.0327 | Q24: 60.3326 | V24: 114.9429
A25: INC08 | H25: 6.887 | M25: 25.192 | V25: 32.079
A26: INC10 | M26: 0.2729 | S26: 9.438 | V26: 9.7109
A27: LMINC08 | C27: 3.0697 | V27: 3.0697
A28: MBI03 | H28: 0.8424 | M28: 1.6252 | V28: 2.4676
A29: 4A | B29: 18 | D29: 2.2465 | F29: 133.1583 | G29: 112.7991 | H29: 1.69 | J29: 1.0581 | N29: 0.2401 | P29: 4.4192 | R29: 4.6177 | V29: 278.229
A30: ESI04 | D30: 1.675 | G30: 8.9754 | P30: 4.4192 | R30: 4.6177 | V30: 19.6873
A31: FUM08 | F31: 6.7299 | G31: 13.8709 | V31: 20.6008
A32: INC03 | B32: 18 | V32: 18
A33: INC06 | D33: 0.5715 | F33: 57.8983 | G33: 19.4194 | J33: 0.64 | V33: 78.5292
A34: INC08 | F34: 68.5301 | G34: 68.8008 | N34: 0.2401 | V34: 137.571
A35: INC10 | G35: 1.7326 | H35: 1.69 | V35: 3.4226
A36: VRD08 | J36: 0.4181 | V36: 0.4181
A37: 4C | D37: 3.2063 | G37: 26.6024 | I37: 7.0191 | K37: 1.377 | L37: 3.8172 | O37: 0.96 | V37: 42.982
A38: ESI04 | K38: 1.377 | O38: 0.96 | V38: 2.337
A39: FUM08 | G39: 3.3124 | L39: 3.8172 | V39: 7.1296
A40: INC08 | D40: 3.2063 | G40: 23.29 | I40: 7.0191 | V40: 33.5154
A41: 4H | C41: 19.9732 | E41: 3.1965 | H41: 6.744 | I41: 7.4944 | M41: 83.0007 | V41: 120.4088
A42: ESI04 | C42: 19.9732 | I42: 2.47 | M42: 2.64 | V42: 25.0832
...

Sheet INC 06
B1: Produto | C1: INC06
B3: M2 | C3: Limite de Produção
C4: 13/mai | D4: 14/mai | E4: Total Geral
B5: Rotas
B6: D | D6: 7.0769 | E6: 7.0769
B7: G | C7: 1.716 | E7: 1.716
B8: Total Geral | C8: 1.716 | D8: 7.0769 | E8: 8.7929

Sheet INC 08
B2: Produto | C2: INC08
B4: M2 | C4: Limite de produção
C5: 12/mai | D5: 13/mai | E5: 14/mai | F5: 15/mai | G5: Total Geral
B6: Rotas
B7: D | E7: 230.541 | G7: 230.541
B8: J | D8: 0.444 | G8: 0.444 | S8: 246
B9: NC | C9: 3.2063 | G9: 3.2063
B10: Retira | D10: 1.3612 | E10: 6.3955 | F10: 21.9802 | G10: 29.7369
B11: Total Geral | C11: 3.2063 | D11: 1.8052 | E11: 236.9365 | F11: 21.9802 | G11: 263.9282

Sheet INC 10
B2: Produto | C2: INC10
B4: M2 | C4: Limite de Produção
C5: 13/mai | D5: Total Geral
B6: Rotas
B7: K | C7: 1.6805 | D7: 1.6805
B8: Total Geral | C8: 1.6805 | D8: 1.6805

Sheet PRIORIDA DO DIA
B1: Rota Nova | C1: (Vários itens)
B3: M2 | C3: Limite de Produção
C4: 07/mai | D4: 11/mai | E4: 12/mai | F4: 13/mai | G4: 14/mai | H4: 15/mai | I4: Total Geral
B5: Rotas
B6: ESI04 | D6: 2.6565 | E6: 7.2489 | F6: 4.5387 | I6: 14.4441
B7: FUM06 | F7: 10.1558 | H7: 13.342 | I7: 23.4978
B8: FUM08 | E8: 1.058 | F8: 6.1838 | G8: 2.4212 | H8: 21.5456 | I8: 31.2086
B9: INC06 | F9: 1.716 | G9: 7.0769 | I9: 8.7929
B10: INC08 | F10: 1.8052 | G10: 236.9365 | H10: 21.9802 | I10: 260.7219
B11: INC10 | F11: 1.6805 | I11: 1.6805
B12: LMINC08 | C12: 3.2327 | D12: 7.1239 | F12: 5.7058 | G12: 6.321 | I12: 22.3834
B13: LMLT06 | F13: 8.6609 | I13: 8.6609
B14: MBI03 | D14: 0.3099 | F14: 0.3094 | G14: 0.2642 | I14: 0.8835
B15: INC03 | H15: 0.3515 | I15: 0.3515
B16: Total Geral | C16: 3.2327 | D16: 10.0903 | E16: 8.3069 | F16: 40.7561 | G16: 253.0198 | H16: 57.2193 | I16: 372.6251

Sheet MODELADO
A1: Tipo Produção | B1: (Vários itens)
A3: Soma de M2 Vendido | B3: Rótulos de Coluna
B4: 30/abr | C4: 07/mai | D4: 14/mai | E4: 15/mai | F4: 18/mai | G4: 19/mai | H4: 20/mai | I4: 21/mai | J4: 22/mai | K4: 25/mai | L4: 26/mai | M4: 27/mai | N4: 28/mai | O4: 01/jun | P4: Total Geral
A5: Rótulos de Linha
A6: FUM06 | E6: 13.342 | P6: 13.342
A7: FUM08 | F7: 0.18 | H7: 8.6565 | P7: 8.8365
A8: INC04 | C8: 13.7293 | I8: 135.2868 | P8: 149.0161
A9: INC06 | J9: 2.08 | N9: 1.4567 | P9: 3.5367
A10: INC08 | D10: 5.526 | E10: 1.5696 | F10: 9.5914 | G10: 2.4857 | I10: 0.663 | K10: 7.2179 | L10: 0.2401 | O10: 1.42 | P10: 28.7137
A11: INC10 | I11: 4.4388 | J11: 6.7516 | M11: 3.5736 | N11: 12.072 | P11: 26.836
A12: INC03 | B12: 18 | P12: 18
A13: ACD10 | E13: 1.944 | P13: 1.944
A14: Total Geral | B14: 18 | C14: 13.7293 | D14: 5.526 | E14: 16.8556 | F14: 9.7714 | G14: 2.4857 | H14: 8.6565 | I14: 140.3886 | J14: 8.8316 | K14: 7.2179 | L14: 0.2401 | M14: 3.5736 | N14: 13.5287 | O14: 1.42 | P14: 250.225

Sheet Base
A1: Hoje | B1: =TODAY() -> 46157
A3: Rota Nova | B3: Madrugada? | C3: m² + perda | D3: Data entrega | E3: Data Proxima | F3: Data sistema (Final de Semana) | G3: Concatenar | H3: Atraso | I3: Dias de atraso | J3: Dias de produção | K3: Pedido | L3: Peça | M3: Seq. | N3: Cód. Barra | O3: Recorte | P3: Cliente | Q3: Rota | R3: M2 Vendido | S3: Peso | T3: Categoria | U3: Produto | V3: Tipo Produção | W3: Largura | X3: Altura | Y3: Emissão | Z3: Previsão | AA3: PCP | AB3: Corte | AC3: Lapidação | AD3: Entrada Linha Singip | AE3: Marcação | AF3: Marcação WaterJet | AG3: Furação | AH3: Furadeira WaterJet Singip 1º Turno | AI3: Bisote | AJ3: Pintura | AK3: Montagem - Laminado/Duplo | AL3: Lavagem | AM3: Forno | AN3: Modelagem | AO3: Serviço Externo | AP3: Inspeção | AQ3: Serigrafia | AR3: Quebra
A4: =VLOOKUP(Q4,'Rotas x Madrugada'!A:C,2,0) -> E | B4: =VLOOKUP(Q4,'Rotas x Madrugada'!A:C,3,0) -> Não | D4: =IF(E4>F4,E4,F4) -> 46147 | E4: =IF(A4="RETIRA",Z4,VLOOKUP(Q4,'Rotas x Madrugada'!A:D,4,0)) -> 46147 | F4: =IF(A4="RETIRA",Z4,Z4+2) -> 46116 | G4: =CONCATENATE(U4,"-",V4) -> LMN1408DEA-PF | H4: =IF(I4<-10,"PROBLEMA",IF(I4<J4,"URGENTE",IF(I4=J4,"PRODUZIR","OK"))) -> PROBLEMA | I4: =Z4-$B$1 -> -43 | J4: =VLOOKUP(G4,'D. Produção'!A:B,2,) -> 4 | K4: 327442 | L4: 0000-0001 | M4: 1 | N4: 5386912 | P4: DA | Q4: 2E | R4: 1.2756 | S4: 25.5128 | T4: 1 | U4: LMN1408DEA | V4: PF | W4: 1118 | X4: 1141 | Y4: 46118.627 | Z4: 46114 | AD4: N/R | AE4: N/R | AF4: N/R | AG4: N/R | AH4: N/R | AI4: N/R | AJ4: N/R | AK4: N/R | AL4: N/R | AM4: N/R | AN4: N/R | AO4: N/R | AP4: N/R | AQ4: N/R
A5: =VLOOKUP(Q5,'Rotas x Madrugada'!A:C,2,0) -> L | B5: =VLOOKUP(Q5,'Rotas x Madrugada'!A:C,3,0) -> Não | D5: =IF(E5>F5,E5,F5) -> 46149 | E5: =IF(A5="RETIRA",Z5,VLOOKUP(Q5,'Rotas x Madrugada'!A:D,4,0)) -> 46149 | F5: =IF(A5="RETIRA",Z5,Z5+2) -> 46144 | G5: =CONCATENATE(U5,"-",V5) -> LMINC08-PF | H5: =IF(I5<-10,"PROBLEMA",IF(I5<J5,"URGENTE",IF(I5=J5,"PRODUZIR","OK"))) -> PROBLEMA | I5: =Z5-$B$1 -> -15 | J5: =VLOOKUP(G5,'D. Produção'!A:B,2,) -> 4 | K5: 331470 | L5: 0000-0005 | M5: 5 | N5: 5424193 | P5: MAV DO BRASIL | Q5: 5L | R5: 3.178 | S5: 63.5607 | T5: 1 | U5: LMINC08 | V5: PF | W5: 2835 | X5: 1121 | Y5: 46135.474 | Z5: 46142 | AD5: N/R | AE5: N/R | AF5: N/R | AG5: N/R | AH5: N/R | AI5: N/R | AJ5: N/R | AK5: N/R | AL5: N/R | AM5: N/R | AN5: N/R | AO5: N/R | AP5: N/R | AQ5: N/R | AR5: 46155.651
A6: =VLOOKUP(Q6,'Rotas x Madrugada'!A:C,2,0) -> NA | B6: =VLOOKUP(Q6,'Rotas x Madrugada'!A:C,3,0) -> Não | D6: =IF(E6>F6,E6,F6) -> 46146 | E6: =IF(A6="RETIRA",Z6,VLOOKUP(Q6,'Rotas x Madrugada'!A:D,4,0)) -> 46146 | F6: =IF(A6="RETIRA",Z6,Z6+2) -> 46144 | G6: =CONCATENATE(U6,"-",V6) -> INC03-LCF | H6: =IF(I6<-10,"PROBLEMA",IF(I6<J6,"URGENTE",IF(I6=J6,"PRODUZIR","OK"))) -> PROBLEMA | I6: =Z6-$B$1 -> -15 | J6: =VLOOKUP(G6,'D. Produção'!A:B,2,) -> #N/A | K6: 334586 | L6: 0000-0009 | M6: 9 | N6: 5447847 | P6: ALPHA VIDROS | Q6: 4A | R6: 2.25 | S6: 16.875 | T6: 1 | U6: INC03 | V6: LCF | W6: 1500 | X6: 1500 | Y6: 46148.681 | Z6: 46142 | AE6: N/R | AF6: N/R | AG6: N/R | AH6: N/R | AI6: N/R | AJ6: N/R | AM6: N/R | AN6: N/R | AO6: N/R | AQ6: N/R
A7: =VLOOKUP(Q7,'Rotas x Madrugada'!A:C,2,0) -> NA | B7: =VLOOKUP(Q7,'Rotas x Madrugada'!A:C,3,0) -> Não | D7: =IF(E7>F7,E7,F7) -> 46146 | E7: =IF(A7="RETIRA",Z7,VLOOKUP(Q7,'Rotas x Madrugada'!A:D,4,0)) -> 46146 | F7: =IF(A7="RETIRA",Z7,Z7+2) -> 46144 | G7: =CONCATENATE(U7,"-",V7) -> INC03-LCF | H7: =IF(I7<-10,"PROBLEMA",IF(I7<J7,"URGENTE",IF(I7=J7,"PRODUZIR","OK"))) -> PROBLEMA | I7: =Z7-$B$1 -> -15 | J7: =VLOOKUP(G7,'D. Produção'!A:B,2,) -> #N/A | K7: 334586 | L7: 0000-0009 | M7: 9 | N7: 5447848 | P7: ALPHA VIDROS | Q7: 4A | R7: 2.25 | S7: 16.875 | T7: 1 | U7: INC03 | V7: LCF | W7: 1500 | X7: 1500 | Y7: 46148.681 | Z7: 46142 | AE7: N/R | AF7: N/R | AG7: N/R | AH7: N/R | AI7: N/R | AJ7: N/R | AM7: N/R | AN7: N/R | AO7: N/R | AQ7: N/R
A8: =VLOOKUP(Q8,'Rotas x Madrugada'!A:C,2,0) -> NA | B8: =VLOOKUP(Q8,'Rotas x Madrugada'!A:C,3,0) -> Não | D8: =IF(E8>F8,E8,F8) -> 46146 | E8: =IF(A8="RETIRA",Z8,VLOOKUP(Q8,'Rotas x Madrugada'!A:D,4,0)) -> 46146 | F8: =IF(A8="RETIRA",Z8,Z8+2) -> 46144 | G8: =CONCATENATE(U8,"-",V8) -> INC03-LCF | H8: =IF(I8<-10,"PROBLEMA",IF(I8<J8,"URGENTE",IF(I8=J8,"PRODUZIR","OK"))) -> PROBLEMA | I8: =Z8-$B$1 -> -15 | J8: =VLOOKUP(G8,'D. Produção'!A:B,2,) -> #N/A | K8: 334586 | L8: 0000-0010 | M8: 10 | N8: 5447849 | P8: ALPHA VIDROS | Q8: 4A | R8: 2.25 | S8: 16.875 | T8: 1 | U8: INC03 | V8: LCF | W8: 1500 | X8: 1500 | Y8: 46148.681 | Z8: 46142 | AE8: N/R | AF8: N/R | AG8: N/R | AH8: N/R | AI8: N/R | AJ8: N/R | AM8: N/R | AN8: N/R | AO8: N/R | AQ8: N/R
A9: =VLOOKUP(Q9,'Rotas x Madrugada'!A:C,2,0) -> NA | B9: =VLOOKUP(Q9,'Rotas x Madrugada'!A:C,3,0) -> Não | D9: =IF(E9>F9,E9,F9) -> 46146 | E9: =IF(A9="RETIRA",Z9,VLOOKUP(Q9,'Rotas x Madrugada'!A:D,4,0)) -> 46146 | F9: =IF(A9="RETIRA",Z9,Z9+2) -> 46144 | G9: =CONCATENATE(U9,"-",V9) -> INC03-LCF | H9: =IF(I9<-10,"PROBLEMA",IF(I9<J9,"URGENTE",IF(I9=J9,"PRODUZIR","OK"))) -> PROBLEMA | I9: =Z9-$B$1 -> -15 | J9: =VLOOKUP(G9,'D. Produção'!A:B,2,) -> #N/A | K9: 334586 | L9: 0000-0010 | M9: 10 | N9: 5447850 | P9: ALPHA VIDROS | Q9: 4A | R9: 2.25 | S9: 16.875 | T9: 1 | U9: INC03 | V9: LCF | W9: 1500 | X9: 1500 | Y9: 46148.681 | Z9: 46142 | AE9: N/R | AF9: N/R | AG9: N/R | AH9: N/R | AI9: N/R | AJ9: N/R | AM9: N/R | AN9: N/R | AO9: N/R | AQ9: N/R
A10: =VLOOKUP(Q10,'Rotas x Madrugada'!A:C,2,0) -> NA | B10: =VLOOKUP(Q10,'Rotas x Madrugada'!A:C,3,0) -> Não | D10: =IF(E10>F10,E10,F10) -> 46146 | E10: =IF(A10="RETIRA",Z10,VLOOKUP(Q10,'Rotas x Madrugada'!A:D,4,0)) -> 46146 | F10: =IF(A10="RETIRA",Z10,Z10+2) -> 46144 | G10: =CONCATENATE(U10,"-",V10) -> INC03-LCF | H10: =IF(I10<-10,"PROBLEMA",IF(I10<J10,"URGENTE",IF(I10=J10,"PRODUZIR","OK"))) -> PROBLEMA | I10: =Z10-$B$1 -> -15 | J10: =VLOOKUP(G10,'D. Produção'!A:B,2,) -> #N/A | K10: 334586 | L10: 0000-0011 | M10: 11 | N10: 5447851 | P10: ALPHA VIDROS | Q10: 4A | R10: 2.25 | S10: 16.875 | T10: 1 | U10: INC03 | V10: LCF | W10: 1500 | X10: 1500 | Y10: 46148.681 | Z10: 46142 | AE10: N/R | AF10: N/R | AG10: N/R | AH10: N/R | AI10: N/R | AJ10: N/R | AM10: N/R | AN10: N/R | AO10: N/R | AQ10: N/R
A11: =VLOOKUP(Q11,'Rotas x Madrugada'!A:C,2,0) -> NA | B11: =VLOOKUP(Q11,'Rotas x Madrugada'!A:C,3,0) -> Não | D11: =IF(E11>F11,E11,F11) -> 46146 | E11: =IF(A11="RETIRA",Z11,VLOOKUP(Q11,'Rotas x Madrugada'!A:D,4,0)) -> 46146 | F11: =IF(A11="RETIRA",Z11,Z11+2) -> 46144 | G11: =CONCATENATE(U11,"-",V11) -> INC03-LCF | H11: =IF(I11<-10,"PROBLEMA",IF(I11<J11,"URGENTE",IF(I11=J11,"PRODUZIR","OK"))) -> PROBLEMA | I11: =Z11-$B$1 -> -15 | J11: =VLOOKUP(G11,'D. Produção'!A:B,2,) -> #N/A | K11: 334586 | L11: 0000-0011 | M11: 11 | N11: 5447852 | P11: ALPHA VIDROS | Q11: 4A | R11: 2.25 | S11: 16.875 | T11: 1 | U11: INC03 | V11: LCF | W11: 1500 | X11: 1500 | Y11: 46148.681 | Z11: 46142 | AE11: N/R | AF11: N/R | AG11: N/R | AH11: N/R | AI11: N/R | AJ11: N/R | AM11: N/R | AN11: N/R | AO11: N/R | AQ11: N/R
A12: =VLOOKUP(Q12,'Rotas x Madrugada'!A:C,2,0) -> NA | B12: =VLOOKUP(Q12,'Rotas x Madrugada'!A:C,3,0) -> Não | D12: =IF(E12>F12,E12,F12) -> 46146 | E12: =IF(A12="RETIRA",Z12,VLOOKUP(Q12,'Rotas x Madrugada'!A:D,4,0)) -> 46146 | F12: =IF(A12="RETIRA",Z12,Z12+2) -> 46144 | G12: =CONCATENATE(U12,"-",V12) -> INC03-LCF | H12: =IF(I12<-10,"PROBLEMA",IF(I12<J12,"URGENTE",IF(I12=J12,"PRODUZIR","OK"))) -> PROBLEMA | I12: =Z12-$B$1 -> -15 | J12: =VLOOKUP(G12,'D. Produção'!A:B,2,) -> #N/A | K12: 334586 | L12: 0000-0012 | M12: 12 | N12: 5447853 | P12: ALPHA VIDROS | Q12: 4A | R12: 2.25 | S12: 16.875 | T12: 1 | U12: INC03 | V12: LCF | W12: 1500 | X12: 1500 | Y12: 46148.681 | Z12: 46142 | AE12: N/R | AF12: N/R | AG12: N/R | AH12: N/R | AI12: N/R | AJ12: N/R | AM12: N/R | AN12: N/R | AO12: N/R | AQ12: N/R
A13: =VLOOKUP(Q13,'Rotas x Madrugada'!A:C,2,0) -> NA | B13: =VLOOKUP(Q13,'Rotas x Madrugada'!A:C,3,0) -> Não | D13: =IF(E13>F13,E13,F13) -> 46146 | E13: =IF(A13="RETIRA",Z13,VLOOKUP(Q13,'Rotas x Madrugada'!A:D,4,0)) -> 46146 | F13: =IF(A13="RETIRA",Z13,Z13+2) -> 46144 | G13: =CONCATENATE(U13,"-",V13) -> INC03-LCF | H13: =IF(I13<-10,"PROBLEMA",IF(I13<J13,"URGENTE",IF(I13=J13,"PRODUZIR","OK"))) -> PROBLEMA | I13: =Z13-$B$1 -> -15 | J13: =VLOOKUP(G13,'D. Produção'!A:B,2,) -> #N/A | K13: 334586 | L13: 0000-0012 | M13: 12 | N13: 5447854 | P13: ALPHA VIDROS | Q13: 4A | R13: 2.25 | S13: 16.875 | T13: 1 | U13: INC03 | V13: LCF | W13: 1500 | X13: 1500 | Y13: 46148.681 | Z13: 46142 | AE13: N/R | AF13: N/R | AG13: N/R | AH13: N/R | AI13: N/R | AJ13: N/R | AM13: N/R | AN13: N/R | AO13: N/R | AQ13: N/R
A14: =VLOOKUP(Q14,'Rotas x Madrugada'!A:C,2,0) -> A | B14: =VLOOKUP(Q14,'Rotas x Madrugada'!A:C,3,0) -> Sim | D14: =IF(E14>F14,E14,F14) -> 46148 | E14: =IF(A14="RETIRA",Z14,VLOOKUP(Q14,'Rotas x Madrugada'!A:D,4,0)) -> 46148 | F14: =IF(A14="RETIRA",Z14,Z14+2) -> 46148 | G14: =CONCATENATE(U14,"-",V14) -> LMLT06-PF | H14: =IF(I14<-10,"PROBLEMA",IF(I14<J14,"URGENTE",IF(I14=J14,"PRODUZIR","OK"))) -> PROBLEMA | I14: =Z14-$B$1 -> -11 | J14: =VLOOKUP(G14,'D. Produção'!A:B,2,) -> 4 | K14: 332341 | L14: 0000-0038 | M14: 38 | N14: 5431228 | P14: FAT 3º - 23 CAMPESTRE | Q14: 7A | R14: 0.4286 | S14: 6.4294 | T14: 1 | U14: LMLT06 | V14: PF | W14: 675 | X14: 635 | Y14: 46139.628 | Z14: 46146 | AD14: N/R | AE14: N/R | AF14: N/R | AG14: N/R | AH14: N/R | AI14: N/R | AJ14: N/R | AK14: N/R | AL14: N/R | AM14: N/R | AN14: N/R | AO14: N/R | AP14: N/R | AQ14: N/R | AR14: 46157.368
A15: =VLOOKUP(Q15,'Rotas x Madrugada'!A:C,2,0) -> A | B15: =VLOOKUP(Q15,'Rotas x Madrugada'!A:C,3,0) -> Sim | D15: =IF(E15>F15,E15,F15) -> 46148 | E15: =IF(A15="RETIRA",Z15,VLOOKUP(Q15,'Rotas x Madrugada'!A:D,4,0)) -> 46148 | F15: =IF(A15="RETIRA",Z15,Z15+2) -> 46148 | G15: =CONCATENATE(U15,"-",V15) -> LMLT06-PF | H15: =IF(I15<-10,"PROBLEMA",IF(I15<J15,"URGENTE",IF(I15=J15,"PRODUZIR","OK"))) -> PROBLEMA | I15: =Z15-$B$1 -> -11 | J15: =VLOOKUP(G15,'D. Produção'!A:B,2,) -> 4 | K15: 332341 | L15: 0000-0046 | M15: 46 | N15: 5431236 | P15: FAT 3º - 23 CAMPESTRE | Q15: 7A | R15: 0.4286 | S15: 6.4294 | T15: 1 | U15: LMLT06 | V15: PF | W15: 675 | X15: 635 | Y15: 46139.628 | Z15: 46146 | AD15: N/R | AE15: N/R | AF15: N/R | AG15: N/R | AH15: N/R | AI15: N/R | AJ15: N/R | AK15: N/R | AL15: N/R | AM15: N/R | AN15: N/R | AO15: N/R | AP15: N/R | AQ15: N/R | AR15: 46157.367
A16: =VLOOKUP(Q16,'Rotas x Madrugada'!A:C,2,0) -> D | B16: =VLOOKUP(Q16,'Rotas x Madrugada'!A:C,3,0) -> Dep. | D16: =IF(E16>F16,E16,F16) -> 46151 | E16: =IF(A16="RETIRA",Z16,VLOOKUP(Q16,'Rotas x Madrugada'!A:D,4,0)) -> 46147 | F16: =IF(A16="RETIRA",Z16,Z16+2) -> 46151 | G16: =CONCATENATE(U16,"-",V16) -> LMINC08-PF | H16: =IF(I16<-10,"PROBLEMA",IF(I16<J16,"URGENTE",IF(I16=J16,"PRODUZIR","OK"))) -> URGENTE | I16: =Z16-$B$1 -> -8 | J16: =VLOOKUP(G16,'D. Produção'!A:B,2,) -> 4 | K16: 331505 | L16: 0000-0001 | M16: 1 | N16: 5424454 | P16: CONSTRULAR LIMEIRA COM DE ESQ | Q16: 6D | R16: 1.17 | S16: 23.4 | T16: 1 | U16: LMINC08 | V16: PF | W16: 1300 | X16: 900 | Y16: 46135.502 | Z16: 46149 | AD16: N/R | AE16: N/R | AF16: N/R | AG16: N/R | AH16: N/R | AI16: N/R | AJ16: N/R | AK16: N/R | AL16: N/R | AM16: N/R | AN16: N/R | AO16: N/R | AP16: N/R | AQ16: N/R | AR16: 46155.626
A17: =VLOOKUP(Q17,'Rotas x Madrugada'!A:C,2,0) -> D | B17: =VLOOKUP(Q17,'Rotas x Madrugada'!A:C,3,0) -> Dep. | D17: =IF(E17>F17,E17,F17) -> 46151 | E17: =IF(A17="RETIRA",Z17,VLOOKUP(Q17,'Rotas x Madrugada'!A:D,4,0)) -> 46147 | F17: =IF(A17="RETIRA",Z17,Z17+2) -> 46151 | G17: =CONCATENATE(U17,"-",V17) -> LMINC08-PF | H17: =IF(I17<-10,"PROBLEMA",IF(I17<J17,"URGENTE",IF(I17=J17,"PRODUZIR","OK"))) -> URGENTE | I17: =Z17-$B$1 -> -8 | J17: =VLOOKUP(G17,'D. Produção'!A:B,2,) -> 4 | K17: 331505 | L17: 0000-0002 | M17: 2 | N17: 5424456 | P17: CONSTRULAR LIMEIRA COM DE ESQ | Q17: 6D | R17: 1.17 | S17: 23.4 | T17: 1 | U17: LMINC08 | V17: PF | W17: 1300 | X17: 900 | Y17: 46135.502 | Z17: 46149 | AD17: N/R | AE17: N/R | AF17: N/R | AG17: N/R | AH17: N/R | AI17: N/R | AJ17: N/R | AK17: N/R | AL17: N/R | AM17: N/R | AN17: N/R | AO17: N/R | AP17: N/R | AQ17: N/R | AR17: 46155.667
A18: =VLOOKUP(Q18,'Rotas x Madrugada'!A:C,2,0) -> #N/A | B18: =VLOOKUP(Q18,'Rotas x Madrugada'!A:C,3,0) -> #N/A | D18: =IF(E18>F18,E18,F18) -> #N/A | E18: =IF(A18="RETIRA",Z18,VLOOKUP(Q18,'Rotas x Madrugada'!A:D,4,0)) -> #N/A | F18: =IF(A18="RETIRA",Z18,Z18+2) -> #N/A | G18: =CONCATENATE(U18,"-",V18) -> INC04-LCF | H18: =IF(I18<-10,"PROBLEMA",IF(I18<J18,"URGENTE",IF(I18=J18,"PRODUZIR","OK"))) -> #N/A | I18: =Z18-$B$1 -> -8 | J18: =VLOOKUP(G18,'D. Produção'!A:B,2,) -> #N/A | K18: 331991 | L18: 0000-0014 | M18: 14 | N18: 5454092 | P18: HOTEL TORIBA | Q18: 4T | R18: 2.405 | S18: 24.05 | T18: 1 | U18: INC04 | V18: LCF | W18: 1300 | X18: 1850 | Y18: 46136.656 | Z18: 46149 | AE18: N/R | AF18: N/R | AG18: N/R | AH18: N/R | AI18: N/R | AJ18: N/R | AM18: N/R | AN18: N/R | AO18: N/R | AQ18: N/R | AR18: 46157.385
A19: =VLOOKUP(Q19,'Rotas x Madrugada'!A:C,2,0) -> #N/A | B19: =VLOOKUP(Q19,'Rotas x Madrugada'!A:C,3,0) -> #N/A | D19: =IF(E19>F19,E19,F19) -> #N/A | E19: =IF(A19="RETIRA",Z19,VLOOKUP(Q19,'Rotas x Madrugada'!A:D,4,0)) -> #N/A | F19: =IF(A19="RETIRA",Z19,Z19+2) -> #N/A | G19: =CONCATENATE(U19,"-",V19) -> INC04-LCF | H19: =IF(I19<-10,"PROBLEMA",IF(I19<J19,"URGENTE",IF(I19=J19,"PRODUZIR","OK"))) -> #N/A | I19: =Z19-$B$1 -> -8 | J19: =VLOOKUP(G19,'D. Produção'!A:B,2,) -> #N/A | K19: 331991 | L19: 0000-0014 | M19: 14 | N19: 5454093 | P19: HOTEL TORIBA | Q19: 4T | R19: 2.405 | S19: 24.05 | T19: 1 | U19: INC04 | V19: LCF | W19: 1300 | X19: 1850 | Y19: 46136.656 | Z19: 46149 | AE19: N/R | AF19: N/R | AG19: N/R | AH19: N/R | AI19: N/R | AJ19: N/R | AM19: N/R | AN19: N/R | AO19: N/R | AQ19: N/R | AR19: 46157.355
A20: =VLOOKUP(Q20,'Rotas x Madrugada'!A:C,2,0) -> #N/A | B20: =VLOOKUP(Q20,'Rotas x Madrugada'!A:C,3,0) -> #N/A | D20: =IF(E20>F20,E20,F20) -> #N/A | E20: =IF(A20="RETIRA",Z20,VLOOKUP(Q20,'Rotas x Madrugada'!A:D,4,0)) -> #N/A | F20: =IF(A20="RETIRA",Z20,Z20+2) -> #N/A | G20: =CONCATENATE(U20,"-",V20) -> INC04-LCF | H20: =IF(I20<-10,"PROBLEMA",IF(I20<J20,"URGENTE",IF(I20=J20,"PRODUZIR","OK"))) -> #N/A | I20: =Z20-$B$1 -> -8 | J20: =VLOOKUP(G20,'D. Produção'!A:B,2,) -> #N/A | K20: 331991 | L20: 0000-0016 | M20: 16 | N20: 5454098 | P20: HOTEL TORIBA | Q20: 4T | R20: 2.405 | S20: 24.05 | T20: 1 | U20: INC04 | V20: LCF | W20: 1300 | X20: 1850 | Y20: 46136.656 | Z20: 46149 | AE20: N/R | AF20: N/R | AG20: N/R | AH20: N/R | AI20: N/R | AJ20: N/R | AM20: N/R | AN20: N/R | AO20: N/R | AQ20: N/R | AR20: 46157.352
A21: =VLOOKUP(Q21,'Rotas x Madrugada'!A:C,2,0) -> #N/A | B21: =VLOOKUP(Q21,'Rotas x Madrugada'!A:C,3,0) -> #N/A | D21: =IF(E21>F21,E21,F21) -> #N/A | E21: =IF(A21="RETIRA",Z21,VLOOKUP(Q21,'Rotas x Madrugada'!A:D,4,0)) -> #N/A | F21: =IF(A21="RETIRA",Z21,Z21+2) -> #N/A | G21: =CONCATENATE(U21,"-",V21) -> INC04-LCF | H21: =IF(I21<-10,"PROBLEMA",IF(I21<J21,"URGENTE",IF(I21=J21,"PRODUZIR","OK"))) -> #N/A | I21: =Z21-$B$1 -> -8 | J21: =VLOOKUP(G21,'D. Produção'!A:B,2,) -> #N/A | K21: 331991 | L21: 0000-0016 | M21: 16 | N21: 5454099 | P21: HOTEL TORIBA | Q21: 4T | R21: 2.405 | S21: 24.05 | T21: 1 | U21: INC04 | V21: LCF | W21: 1300 | X21: 1850 | Y21: 46136.656 | Z21: 46149 | AE21: N/R | AF21: N/R | AG21: N/R | AH21: N/R | AI21: N/R | AJ21: N/R | AM21: N/R | AN21: N/R | AO21: N/R | AQ21: N/R | AR21: 46157.386
A22: =VLOOKUP(Q22,'Rotas x Madrugada'!A:C,2,0) -> #N/A | B22: =VLOOKUP(Q22,'Rotas x Madrugada'!A:C,3,0) -> #N/A | D22: =IF(E22>F22,E22,F22) -> #N/A | E22: =IF(A22="RETIRA",Z22,VLOOKUP(Q22,'Rotas x Madrugada'!A:D,4,0)) -> #N/A | F22: =IF(A22="RETIRA",Z22,Z22+2) -> #N/A | G22: =CONCATENATE(U22,"-",V22) -> INC04-LCF | H22: =IF(I22<-10,"PROBLEMA",IF(I22<J22,"URGENTE",IF(I22=J22,"PRODUZIR","OK"))) -> #N/A | I22: =Z22-$B$1 -> -8 | J22: =VLOOKUP(G22,'D. Produção'!A:B,2,) -> #N/A | K22: 331991 | L22: 0000-0017 | M22: 17 | N22: 5454102 | P22: HOTEL TORIBA | Q22: 4T | R22: 2.2718 | S22: 22.718 | T22: 1 | U22: INC04 | V22: LCF | W22: 1228 | X22: 1850 | Y22: 46136.656 | Z22: 46149 | AE22: N/R | AF22: N/R | AG22: N/R | AH22: N/R | AI22: N/R | AJ22: N/R | AM22: N/R | AN22: N/R | AO22: N/R | AQ22: N/R | AR22: 46157.344
A23: =VLOOKUP(Q23,'Rotas x Madrugada'!A:C,2,0) -> #N/A | B23: =VLOOKUP(Q23,'Rotas x Madrugada'!A:C,3,0) -> #N/A | D23: =IF(E23>F23,E23,F23) -> #N/A | E23: =IF(A23="RETIRA",Z23,VLOOKUP(Q23,'Rotas x Madrugada'!A:D,4,0)) -> #N/A | F23: =IF(A23="RETIRA",Z23,Z23+2) -> #N/A | G23: =CONCATENATE(U23,"-",V23) -> INC04-LCF | H23: =IF(I23<-10,"PROBLEMA",IF(I23<J23,"URGENTE",IF(I23=J23,"PRODUZIR","OK"))) -> #N/A | I23: =Z23-$B$1 -> -8 | J23: =VLOOKUP(G23,'D. Produção'!A:B,2,) -> #N/A | K23: 331996 | L23: 0000-0002 | M23: 2 | N23: 5454126 | P23: HOTEL TORIBA | Q23: 4T | R23: 1.8375 | S23: 18.375 | T23: 1 | U23: INC04 | V23: LCF | W23: 1225 | X23: 1500 | Y23: 46136.656 | Z23: 46149 | AE23: N/R | AF23: N/R | AG23: N/R | AH23: N/R | AI23: N/R | AJ23: N/R | AM23: N/R | AN23: N/R | AO23: N/R | AQ23: N/R | AR23: 46157.377
A24: =VLOOKUP(Q24,'Rotas x Madrugada'!A:C,2,0) -> D | B24: =VLOOKUP(Q24,'Rotas x Madrugada'!A:C,3,0) -> Dep. | D24: =IF(E24>F24,E24,F24) -> 46151 | E24: =IF(A24="RETIRA",Z24,VLOOKUP(Q24,'Rotas x Madrugada'!A:D,4,0)) -> 46147 | F24: =IF(A24="RETIRA",Z24,Z24+2) -> 46151 | G24: =CONCATENATE(U24,"-",V24) -> LMINC08-PF | H24: =IF(I24<-10,"PROBLEMA",IF(I24<J24,"URGENTE",IF(I24=J24,"PRODUZIR","OK"))) -> URGENTE | I24: =Z24-$B$1 -> -8 | J24: =VLOOKUP(G24,'D. Produção'!A:B,2,) -> 4 | K24: 332210 | L24: 0000-0001 | M24: 1 | N24: 5430277 | P24: TAMBAU ULIBOX | Q24: 6D | R24: 0.8927 | S24: 17.8542 | T24: 1 | U24: LMINC08 | V24: PF | W24: 910 | X24: 981 | Y24: 46139.421 | Z24: 46149 | AD24: N/R | AE24: N/R | AF24: N/R | AG24: N/R | AH24: N/R | AI24: N/R | AJ24: N/R | AK24: N/R | AL24: N/R | AM24: N/R | AN24: N/R | AO24: N/R | AP24: N/R | AQ24: N/R
A25: =VLOOKUP(Q25,'Rotas x Madrugada'!A:C,2,0) -> NC | B25: =VLOOKUP(Q25,'Rotas x Madrugada'!A:C,3,0) -> Não | D25: =IF(E25>F25,E25,F25) -> 46153 | E25: =IF(A25="RETIRA",Z25,VLOOKUP(Q25,'Rotas x Madrugada'!A:D,4,0)) -> 46146 | F25: =IF(A25="RETIRA",Z25,Z25+2) -> 46153 | G25: =CONCATENATE(U25,"-",V25) -> ESI04-EFB | H25: =IF(I25<-10,"PROBLEMA",IF(I25<J25,"URGENTE",IF(I25=J25,"PRODUZIR","OK"))) -> URGENTE | I25: =Z25-$B$1 -> -6 | J25: =VLOOKUP(G25,'D. Produção'!A:B,2,) -> 1 | K25: 334141 | L25: 0000-0001 | M25: 1 | N25: 5444324 | P25: J E VIDROS | Q25: 4C | R25: 1.377 | S25: 13.77 | T25: 1 | U25: ESI04 | V25: EFB | W25: 1530 | X25: 900 | Y25: 46147.612 | Z25: 46151 | AD25: N/R | AE25: N/R | AF25: N/R | AG25: N/R | AH25: N/R | AJ25: N/R | AK25: N/R | AM25: N/R | AN25: N/R | AO25: N/R | AQ25: N/R | AR25: 46155.346
A26: =VLOOKUP(Q26,'Rotas x Madrugada'!A:C,2,0) -> B | B26: =VLOOKUP(Q26,'Rotas x Madrugada'!A:C,3,0) -> Dep. | D26: =IF(E26>F26,E26,F26) -> 46155 | E26: =IF(A26="RETIRA",Z26,VLOOKUP(Q26,'Rotas x Madrugada'!A:D,4,0)) -> 46146 | F26: =IF(A26="RETIRA",Z26,Z26+2) -> 46155 | G26: =CONCATENATE(U26,"-",V26) -> LMINC08-PF | H26: =IF(I26<-10,"PROBLEMA",IF(I26<J26,"URGENTE",IF(I26=J26,"PRODUZIR","OK"))) -> URGENTE | I26: =Z26-$B$1 -> -4 | J26: =VLOOKUP(G26,'D. Produção'!A:B,2,) -> 4 | K26: 332389 | L26: 0000-0001 | M26: 1 | N26: 5431757 | P26: FAT 3º - 3989 MAGNA | Q26: 3B | R26: 3.0697 | S26: 61.3939 | T26: 1 | U26: LMINC08 | V26: PF | W26: 2284 | X26: 1344 | Y26: 46139.688 | Z26: 46153 | AD26: N/R | AE26: N/R | AF26: N/R | AG26: N/R | AH26: N/R | AI26: N/R | AJ26: N/R | AK26: N/R | AL26: N/R | AM26: N/R | AN26: N/R | AO26: N/R | AP26: N/R | AQ26: N/R | AR26: 46155.627
A27: =VLOOKUP(Q27,'Rotas x Madrugada'!A:C,2,0) -> K | B27: =VLOOKUP(Q27,'Rotas x Madrugada'!A:C,3,0) -> Sim | D27: =IF(E27>F27,E27,F27) -> 46155 | E27: =IF(A27="RETIRA",Z27,VLOOKUP(Q27,'Rotas x Madrugada'!A:D,4,0)) -> 46146 | F27: =IF(A27="RETIRA",Z27,Z27+2) -> 46155 | G27: =CONCATENATE(U27,"-",V27) -> LMINC08-PF | H27: =IF(I27<-10,"PROBLEMA",IF(I27<J27,"URGENTE",IF(I27=J27,"PRODUZIR","OK"))) -> URGENTE | I27: =Z27-$B$1 -> -4 | J27: =VLOOKUP(G27,'D. Produção'!A:B,2,) -> 4 | K27: 332848 | L27: 0000-0006 | M27: 6 | N27: 5435879 | P27: MG ALUM E VIDRO | Q27: 9K | R27: 1.0605 | S27: 21.21 | T27: 1 | U27: LMINC08 | V27: PF | W27: 1010 | X27: 1050 | Y27: 46141.376 | Z27: 46153 | AD27: N/R | AE27: N/R | AF27: N/R | AG27: N/R | AH27: N/R | AI27: N/R | AJ27: N/R | AK27: N/R | AL27: N/R | AM27: N/R | AN27: N/R | AO27: N/R | AP27: N/R | AQ27: N/R | AR27: 46154.666
A28: =VLOOKUP(Q28,'Rotas x Madrugada'!A:C,2,0) -> K | B28: =VLOOKUP(Q28,'Rotas x Madrugada'!A:C,3,0) -> Sim | D28: =IF(E28>F28,E28,F28) -> 46155 | E28: =IF(A28="RETIRA",Z28,VLOOKUP(Q28,'Rotas x Madrugada'!A:D,4,0)) -> 46146 | F28: =IF(A28="RETIRA",Z28,Z28+2) -> 46155 | G28: =CONCATENATE(U28,"-",V28) -> LMINC08-PF | H28: =IF(I28<-10,"PROBLEMA",IF(I28<J28,"URGENTE",IF(I28=J28,"PRODUZIR","OK"))) -> URGENTE | I28: =Z28-$B$1 -> -4 | J28: =VLOOKUP(G28,'D. Produção'!A:B,2,) -> 4 | K28: 332848 | L28: 0000-0008 | M28: 8 | N28: 5435881 | P28: MG ALUM E VIDRO | Q28: 9K | R28: 1.1968 | S28: 23.937 | T28: 1 | U28: LMINC08 | V28: PF | W28: 1185 | X28: 1010 | Y28: 46141.376 | Z28: 46153 | AD28: N/R | AE28: N/R | AF28: N/R | AG28: N/R | AH28: N/R | AI28: N/R | AJ28: N/R | AK28: N/R | AL28: N/R | AM28: N/R | AN28: N/R | AO28: N/R | AP28: N/R | AQ28: N/R | AR28: 46154.666
A29: =VLOOKUP(Q29,'Rotas x Madrugada'!A:C,2,0) -> K | B29: =VLOOKUP(Q29,'Rotas x Madrugada'!A:C,3,0) -> Sim | D29: =IF(E29>F29,E29,F29) -> 46155 | E29: =IF(A29="RETIRA",Z29,VLOOKUP(Q29,'Rotas x Madrugada'!A:D,4,0)) -> 46146 | F29: =IF(A29="RETIRA",Z29,Z29+2) -> 46155 | G29: =CONCATENATE(U29,"-",V29) -> LMINC08-PF | H29: =IF(I29<-10,"PROBLEMA",IF(I29<J29,"URGENTE",IF(I29=J29,"PRODUZIR","OK"))) -> URGENTE | I29: =Z29-$B$1 -> -4 | J29: =VLOOKUP(G29,'D. Produção'!A:B,2,) -> 4 | K29: 332848 | L29: 0000-0010 | M29: 10 | N29: 5435883 | P29: MG ALUM E VIDRO | Q29: 9K | R29: 0.9435 | S29: 18.87 | T29: 1 | U29: LMINC08 | V29: PF | W29: 1110 | X29: 850 | Y29: 46141.376 | Z29: 46153 | AD29: N/R | AE29: N/R | AF29: N/R | AG29: N/R | AH29: N/R | AI29: N/R | AJ29: N/R | AK29: N/R | AL29: N/R | AM29: N/R | AN29: N/R | AO29: N/R | AP29: N/R | AQ29: N/R
A30: =VLOOKUP(Q30,'Rotas x Madrugada'!A:C,2,0) -> K | B30: =VLOOKUP(Q30,'Rotas x Madrugada'!A:C,3,0) -> Sim | D30: =IF(E30>F30,E30,F30) -> 46155 | E30: =IF(A30="RETIRA",Z30,VLOOKUP(Q30,'Rotas x Madrugada'!A:D,4,0)) -> 46146 | F30: =IF(A30="RETIRA",Z30,Z30+2) -> 46155 | G30: =CONCATENATE(U30,"-",V30) -> LMINC08-PF | H30: =IF(I30<-10,"PROBLEMA",IF(I30<J30,"URGENTE",IF(I30=J30,"PRODUZIR","OK"))) -> URGENTE | I30: =Z30-$B$1 -> -4 | J30: =VLOOKUP(G30,'D. Produção'!A:B,2,) -> 4 | K30: 332848 | L30: 0000-0012 | M30: 12 | N30: 5435885 | P30: MG ALUM E VIDRO | Q30: 9K | R30: 0.8534 | S30: 17.069 | T30: 1 | U30: LMINC08 | V30: PF | W30: 845 | X30: 1010 | Y30: 46141.376 | Z30: 46153 | AD30: N/R | AE30: N/R | AF30: N/R | AG30: N/R | AH30: N/R | AI30: N/R | AJ30: N/R | AK30: N/R | AL30: N/R | AM30: N/R | AN30: N/R | AO30: N/R | AP30: N/R | AQ30: N/R
A31: =VLOOKUP(Q31,'Rotas x Madrugada'!A:C,2,0) -> NH | B31: =VLOOKUP(Q31,'Rotas x Madrugada'!A:C,3,0) -> Não | D31: =IF(E31>F31,E31,F31) -> 46155 | E31: =IF(A31="RETIRA",Z31,VLOOKUP(Q31,'Rotas x Madrugada'!A:D,4,0)) -> 46146 | F31: =IF(A31="RETIRA",Z31,Z31+2) -> 46155 | G31: =CONCATENATE(U31,"-",V31) -> ESI04-EFB | H31: =IF(I31<-10,"PROBLEMA",IF(I31<J31,"URGENTE",IF(I31=J31,"PRODUZIR","OK"))) -> URGENTE | I31: =Z31-$B$1 -> -4 | J31: =VLOOKUP(G31,'D. Produção'!A:B,2,) -> 1 | K31: 334020 | L31: 0000-0001 | M31: 1 | N31: 5442919 | P31: CONSUMIDOR DIVIMAX HORTOLÂNDIA | Q31: 4H | R31: 0.5768 | S31: 5.768 | T31: 1 | U31: ESI04 | V31: EFB | W31: 852 | X31: 677 | Y31: 46147.455 | Z31: 46153 | AD31: N/R | AE31: N/R | AF31: N/R | AG31: N/R | AH31: N/R | AJ31: N/R | AK31: N/R | AM31: N/R | AN31: N/R | AO31: N/R | AQ31: N/R | AR31: 46155.43
A32: =VLOOKUP(Q32,'Rotas x Madrugada'!A:C,2,0) -> NH | B32: =VLOOKUP(Q32,'Rotas x Madrugada'!A:C,3,0) -> Não | D32: =IF(E32>F32,E32,F32) -> 46155 | E32: =IF(A32="RETIRA",Z32,VLOOKUP(Q32,'Rotas x Madrugada'!A:D,4,0)) -> 46146 | F32: =IF(A32="RETIRA",Z32,Z32+2) -> 46155 | G32: =CONCATENATE(U32,"-",V32) -> ESI04-EF | H32: =IF(I32<-10,"PROBLEMA",IF(I32<J32,"URGENTE",IF(I32=J32,"PRODUZIR","OK"))) -> URGENTE | I32: =Z32-$B$1 -> -4 | J32: =VLOOKUP(G32,'D. Produção'!A:B,2,) -> 1 | K32: 334021 | L32: 0000-0001 | M32: 1 | N32: 5442920 | P32: SOS ESQ | Q32: 4H | R32: 3.1964 | S32: 31.964 | T32: 1 | U32: ESI04 | V32: EF | W32: 1310 | X32: 2440 | Y32: 46147.456 | Z32: 46153 | AE32: N/R | AF32: N/R | AG32: N/R | AH32: N/R | AI32: N/R | AJ32: N/R | AK32: N/R | AM32: N/R | AN32: N/R | AO32: N/R | AQ32: N/R
A33: =VLOOKUP(Q33,'Rotas x Madrugada'!A:C,2,0) -> NH | B33: =VLOOKUP(Q33,'Rotas x Madrugada'!A:C,3,0) -> Não | D33: =IF(E33>F33,E33,F33) -> 46155 | E33: =IF(A33="RETIRA",Z33,VLOOKUP(Q33,'Rotas x Madrugada'!A:D,4,0)) -> 46146 | F33: =IF(A33="RETIRA",Z33,Z33+2) -> 46155 | G33: =CONCATENATE(U33,"-",V33) -> ESI04-EFB | H33: =IF(I33<-10,"PROBLEMA",IF(I33<J33,"URGENTE",IF(I33=J33,"PRODUZIR","OK"))) -> URGENTE | I33: =Z33-$B$1 -> -4 | J33: =VLOOKUP(G33,'D. Produção'!A:B,2,) -> 1 | K33: 334279 | L33: 0000-0001 | M33: 1 | N33: 5445658 | P33: BONFIM VIDROS | Q33: 4H | R33: 2.22 | S33: 22.2 | T33: 1 | U33: ESI04 | V33: EFB | W33: 1500 | X33: 1480 | Y33: 46147.714 | Z33: 46153 | AD33: N/R | AE33: N/R | AF33: N/R | AG33: N/R | AH33: N/R | AJ33: N/R | AK33: N/R | AM33: N/R | AN33: N/R | AO33: N/R | AQ33: N/R
A34: =VLOOKUP(Q34,'Rotas x Madrugada'!A:C,2,0) -> NH | B34: =VLOOKUP(Q34,'Rotas x Madrugada'!A:C,3,0) -> Não | D34: =IF(E34>F34,E34,F34) -> 46155 | E34: =IF(A34="RETIRA",Z34,VLOOKUP(Q34,'Rotas x Madrugada'!A:D,4,0)) -> 46146 | F34: =IF(A34="RETIRA",Z34,Z34+2) -> 46155 | G34: =CONCATENATE(U34,"-",V34) -> ESI04-EF | H34: =IF(I34<-10,"PROBLEMA",IF(I34<J34,"URGENTE",IF(I34=J34,"PRODUZIR","OK"))) -> URGENTE | I34: =Z34-$B$1 -> -4 | J34: =VLOOKUP(G34,'D. Produção'!A:B,2,) -> 1 | K34: 334576 | L34: 0000-0001 | M34: 1 | N34: 5447780 | P34: CONSUMIDOR DIVIMAX HORTOLÂNDIA | Q34: 4H | R34: 1.8 | S34: 18 | T34: 1 | U34: ESI04 | V34: EF | W34: 900 | X34: 2000 | Y34: 46148.678 | Z34: 46153 | AE34: N/R | AF34: N/R | AG34: N/R | AH34: N/R | AI34: N/R | AJ34: N/R | AK34: N/R | AM34: N/R | AN34: N/R | AO34: N/R | AQ34: N/R
A35: =VLOOKUP(Q35,'Rotas x Madrugada'!A:C,2,0) -> NH | B35: =VLOOKUP(Q35,'Rotas x Madrugada'!A:C,3,0) -> Não | D35: =IF(E35>F35,E35,F35) -> 46155 | E35: =IF(A35="RETIRA",Z35,VLOOKUP(Q35,'Rotas x Madrugada'!A:D,4,0)) -> 46146 | F35: =IF(A35="RETIRA",Z35,Z35+2) -> 46155 | G35: =CONCATENATE(U35,"-",V35) -> ESI04-EF | H35: =IF(I35<-10,"PROBLEMA",IF(I35<J35,"URGENTE",IF(I35=J35,"PRODUZIR","OK"))) -> URGENTE | I35: =Z35-$B$1 -> -4 | J35: =VLOOKUP(G35,'D. Produção'!A:B,2,) -> 1 | K35: 334576 | L35: 0000-0002 | M35: 2 | N35: 5447781 | P35: CONSUMIDOR DIVIMAX HORTOLÂNDIA | Q35: 4H | R35: 1.8 | S35: 18 | T35: 1 | U35: ESI04 | V35: EF | W35: 900 | X35: 2000 | Y35: 46148.678 | Z35: 46153 | AE35: N/R | AF35: N/R | AG35: N/R | AH35: N/R | AI35: N/R | AJ35: N/R | AK35: N/R | AM35: N/R | AN35: N/R | AO35: N/R | AQ35: N/R
A36: =VLOOKUP(Q36,'Rotas x Madrugada'!A:C,2,0) -> NH | B36: =VLOOKUP(Q36,'Rotas x Madrugada'!A:C,3,0) -> Não | D36: =IF(E36>F36,E36,F36) -> 46155 | E36: =IF(A36="RETIRA",Z36,VLOOKUP(Q36,'Rotas x Madrugada'!A:D,4,0)) -> 46146 | F36: =IF(A36="RETIRA",Z36,Z36+2) -> 46155 | G36: =CONCATENATE(U36,"-",V36) -> ESI04-EF | H36: =IF(I36<-10,"PROBLEMA",IF(I36<J36,"URGENTE",IF(I36=J36,"PRODUZIR","OK"))) -> URGENTE | I36: =Z36-$B$1 -> -4 | J36: =VLOOKUP(G36,'D. Produção'!A:B,2,) -> 1 | K36: 334576 | L36: 0000-0003 | M36: 3 | N36: 5447782 | P36: CONSUMIDOR DIVIMAX HORTOLÂNDIA | Q36: 4H | R36: 1.8 | S36: 18 | T36: 1 | U36: ESI04 | V36: EF | W36: 900 | X36: 2000 | Y36: 46148.678 | Z36: 46153 | AE36: N/R | AF36: N/R | AG36: N/R | AH36: N/R | AI36: N/R | AJ36: N/R | AK36: N/R | AM36: N/R | AN36: N/R | AO36: N/R | AQ36: N/R
A37: =VLOOKUP(Q37,'Rotas x Madrugada'!A:C,2,0) -> NH | B37: =VLOOKUP(Q37,'Rotas x Madrugada'!A:C,3,0) -> Não | D37: =IF(E37>F37,E37,F37) -> 46155 | E37: =IF(A37="RETIRA",Z37,VLOOKUP(Q37,'Rotas x Madrugada'!A:D,4,0)) -> 46146 | F37: =IF(A37="RETIRA",Z37,Z37+2) -> 46155 | G37: =CONCATENATE(U37,"-",V37) -> ESI04-EF | H37: =IF(I37<-10,"PROBLEMA",IF(I37<J37,"URGENTE",IF(I37=J37,"PRODUZIR","OK"))) -> URGENTE | I37: =Z37-$B$1 -> -4 | J37: =VLOOKUP(G37,'D. Produção'!A:B,2,) -> 1 | K37: 334576 | L37: 0000-0004 | M37: 4 | N37: 5447783 | P37: CONSUMIDOR DIVIMAX HORTOLÂNDIA | Q37: 4H | R37: 1.8 | S37: 18 | T37: 1 | U37: ESI04 | V37: EF | W37: 900 | X37: 2000 | Y37: 46148.678 | Z37: 46153 | AE37: N/R | AF37: N/R | AG37: N/R | AH37: N/R | AI37: N/R | AJ37: N/R | AK37: N/R | AM37: N/R | AN37: N/R | AO37: N/R | AQ37: N/R
A38: =VLOOKUP(Q38,'Rotas x Madrugada'!A:C,2,0) -> NH | B38: =VLOOKUP(Q38,'Rotas x Madrugada'!A:C,3,0) -> Não | D38: =IF(E38>F38,E38,F38) -> 46155 | E38: =IF(A38="RETIRA",Z38,VLOOKUP(Q38,'Rotas x Madrugada'!A:D,4,0)) -> 46146 | F38: =IF(A38="RETIRA",Z38,Z38+2) -> 46155 | G38: =CONCATENATE(U38,"-",V38) -> ESI04-EF | H38: =IF(I38<-10,"PROBLEMA",IF(I38<J38,"URGENTE",IF(I38=J38,"PRODUZIR","OK"))) -> URGENTE | I38: =Z38-$B$1 -> -4 | J38: =VLOOKUP(G38,'D. Produção'!A:B,2,) -> 1 | K38: 334576 | L38: 0000-0005 | M38: 5 | N38: 5447784 | P38: CONSUMIDOR DIVIMAX HORTOLÂNDIA | Q38: 4H | R38: 1.8 | S38: 18 | T38: 1 | U38: ESI04 | V38: EF | W38: 900 | X38: 2000 | Y38: 46148.678 | Z38: 46153 | AE38: N/R | AF38: N/R | AG38: N/R | AH38: N/R | AI38: N/R | AJ38: N/R | AK38: N/R | AM38: N/R | AN38: N/R | AO38: N/R | AQ38: N/R
A39: =VLOOKUP(Q39,'Rotas x Madrugada'!A:C,2,0) -> NH | B39: =VLOOKUP(Q39,'Rotas x Madrugada'!A:C,3,0) -> Não | D39: =IF(E39>F39,E39,F39) -> 46155 | E39: =IF(A39="RETIRA",Z39,VLOOKUP(Q39,'Rotas x Madrugada'!A:D,4,0)) -> 46146 | F39: =IF(A39="RETIRA",Z39,Z39+2) -> 46155 | G39: =CONCATENATE(U39,"-",V39) -> ESI04-EE | H39: =IF(I39<-10,"PROBLEMA",IF(I39<J39,"URGENTE",IF(I39=J39,"PRODUZIR","OK"))) -> #N/A | I39: =Z39-$B$1 -> -4 | J39: =VLOOKUP(G39,'D. Produção'!A:B,2,) -> #N/A | K39: 334576 | L39: 0000-0006 | M39: 6 | N39: 5447785 | P39: CONSUMIDOR DIVIMAX HORTOLÂNDIA | Q39: 4H | R39: 1.375 | S39: 13.75 | T39: 1 | U39: ESI04 | V39: EE | W39: 1100 | X39: 1250 | Y39: 46148.678 | Z39: 46153 | AI39: N/R | AJ39: N/R | AK39: N/R | AM39: N/R | AN39: N/R | AO39: N/R | AQ39: N/R
A40: =VLOOKUP(Q40,'Rotas x Madrugada'!A:C,2,0) -> NH | B40: =VLOOKUP(Q40,'Rotas x Madrugada'!A:C,3,0) -> Não | D40: =IF(E40>F40,E40,F40) -> 46155 | E40: =IF(A40="RETIRA",Z40,VLOOKUP(Q40,'Rotas x Madrugada'!A:D,4,0)) -> 46146 | F40: =IF(A40="RETIRA",Z40,Z40+2) -> 46155 | G40: =CONCATENATE(U40,"-",V40) -> ESI04-EE | H40: =IF(I40<-10,"PROBLEMA",IF(I40<J40,"URGENTE",IF(I40=J40,"PRODUZIR","OK"))) -> #N/A | I40: =Z40-$B$1 -> -4 | J40: =VLOOKUP(G40,'D. Produção'!A:B,2,) -> #N/A | K40: 334576 | L40: 0000-0007 | M40: 7 | N40: 5447786 | P40: CONSUMIDOR DIVIMAX HORTOLÂNDIA | Q40: 4H | R40: 1.375 | S40: 13.75 | T40: 1 | U40: ESI04 | V40: EE | W40: 1100 | X40: 1250 | Y40: 46148.678 | Z40: 46153 | AI40: N/R | AJ40: N/R | AK40: N/R | AM40: N/R | AN40: N/R | AO40: N/R | AQ40: N/R
A41: =VLOOKUP(Q41,'Rotas x Madrugada'!A:C,2,0) -> NH | B41: =VLOOKUP(Q41,'Rotas x Madrugada'!A:C,3,0) -> Não | D41: =IF(E41>F41,E41,F41) -> 46155 | E41: =IF(A41="RETIRA",Z41,VLOOKUP(Q41,'Rotas x Madrugada'!A:D,4,0)) -> 46146 | F41: =IF(A41="RETIRA",Z41,Z41+2) -> 46155 | G41: =CONCATENATE(U41,"-",V41) -> ESI04-EFB | H41: =IF(I41<-10,"PROBLEMA",IF(I41<J41,"URGENTE",IF(I41=J41,"PRODUZIR","OK"))) -> URGENTE | I41: =Z41-$B$1 -> -4 | J41: =VLOOKUP(G41,'D. Produção'!A:B,2,) -> 1 | K41: 334576 | L41: 0000-0008 | M41: 8 | N41: 5447787 | P41: CONSUMIDOR DIVIMAX HORTOLÂNDIA | Q41: 4H | R41: 2.23 | S41: 22.3 | T41: 1 | U41: ESI04 | V41: EFB | W41: 2230 | X41: 1000 | Y41: 46148.678 | Z41: 46153 | AD41: N/R | AE41: N/R | AF41: N/R | AG41: N/R | AH41: N/R | AJ41: N/R | AK41: N/R | AM41: N/R | AN41: N/R | AO41: N/R | AQ41: N/R
...

Sheet D. Produção
A1: Concatenar | B1: Dias de produção
A2: ARM06-CC | B2: 1
A3: BRZ06-TF | B3: 1
A4: ESI04-EF | B4: 1
A5: ESI04-EFA | B5: 1
A6: ESI04-EFB | B6: 1
A7: ESI04-EFQ | B7: 1
A8: ESI06-EE | B8: 1
A9: ESI06-EF | B9: 1
A10: ESIBRZ04-EF | B10: 1
A11: FUM04-CCNH | B11: 1
A12: FUM06-TEK. | B12: 2
A13: FUM06-TF | B13: 2
... A70: VRD08-TE12 | B70: 2

Sheet ATRASO B.O
A1: Atraso | B1: (Tudo)
A2: Rota Nova | B2: (Tudo)
A4: Soma de M2 Vendido | B4: Rótulos de Coluna
A5: Rótulos de Linha | B5: -8 | C5: -6 | D5: -4 | E5: -3 | F5: -2 | G5: -1 | H5: 0 | I5: 1 | J5: 2 | K5: 3 | L5: 4 | M5: 5 | N5: 6 | O5: 7 | P5: 9 | Q5: 10 | R5: 11 | S5: 15 | T5: -11 | U5: -43 | V5: -15 | W5: -46157 | X5: Total Geral
A6: ACD06 | N6: 1.4635 | Q6: 6.4969 | X6: 7.9604
A7: AMB04 | H7: 0.9613 | X7: 0.9613
A8: ESI04 | C8: 1.377 | D8: 22.6297 | E8: 8.9239 | F8: 4.5387 | I8: 8.1443 | J8: 20.0834 | K8: 2.64 | L8: 8.9754 | M8: 8.1229 | N8: 4.39 | P8: 4.6177 | R8: 1.45 | S8: 0.64 | X8: 96.533
A9: FUM04 | O9: 0.2896 | X9: 0.2896
A10: FUM06 | F10: 10.1558 | H10: 13.342 | X10: 23.4978
A11: FUM08 | E11: 1.058 | F11: 9.3803 | G11: 7.6678 | H11: 57.6571 | K11: 3.9461 | L11: 49.4751 | M11: 10.1129 | N11: 21.0628 | X11: 160.3601
A12: INC03 | H12: 0.3515 | V12: 18 | X12: 18.3515
A13: INC04 | B13: 13.7293 | N13: 135.2868 | X13: 149.0161
A14: INC12 | L14: 10.6543 | X14: 10.6543
A15: LMINC06 | K15: 3.5196 | L15: 5.1336 | X15: 8.6532
A16: LMINC08 | B16: 3.2327 | D16: 7.1239 | F16: 5.7058 | G16: 6.321 | H16: 4.228 | M16: 4.8326 | N16: 3.7875 | Q16: 86.0589 | R16: 16.6759 | V16: 3.178 | X16: 141.1443
A17: LMLT06 | E17: 10.386 | F17: 8.6609 | H17: 9.2203 | K17: 50.3961 | L17: 3.5356 | M17: 5.5583 | R17: 6.8332 | T17: 0.8572 | X17: 95.4476
A18: LMLT06VMT | K18: 1.0885 | X18: 1.0885
A19: LMLT08 | H19: 2.2176 | K19: 7.1886 | L19: 4.2238 | N19: 5.4601 | X19: 19.0901
A20: LMN1408 | N20: 7.1344 | X20: 7.1344
A21: LMN1408DEA | U21: 1.2756 | X21: 1.2756
A22: LMSV3208 | K22: 0.9588 | X22: 0.9588
A23: MBI03 | D23: 0.3099 | F23: 0.3094 | G23: 0.2642 | K23: 14.642 | L23: 2.8718 | M23: 21.2603 | O23: 0.7947 | R23: 3.2608 | X23: 43.7131
A24: MBI08 | K24: 0.711 | X24: 0.711
A25: VRD08 | L25: 2.0632 | O25: 0.4181 | X25: 2.4813
A26: (vazio) | W26: 4031.3598 | X26: 4031.3598
A27: Total Geral | B27: 16.962 | C27: 1.377 | D27: 30.0635 | E27: 20.3679 | F27: 38.7509 | G27: 14.253 | H27: 87.9778 | I27: 8.1443 | J27: 20.0834 | K27: 85.0907 | L27: 86.9328 | M27: 49.887 | N27: 178.5851 | O27: 1.5024 | P27: 4.6177 | Q27: 92.5558 | R27: 28.2199 | S27: 0.64 | T27: 0.8572 | U27: 1.2756 | V27: 21.178 | W27: 4031.3598 | X27: 4820.6818

Sheet Rotas x Madrugada
A1: Rota | B1: Rota Nova | C1: Madrugada? | D1: PRÓXIMA ENTREGA
A2: 7A | B2: A | C2: Sim | D2: 46148
A3: 3B | B3: B | C3: Dep. | D3: 46146
A4: 7C | B4: C | C4: Sim | D4: 46148
A5: 6D | B5: D | C5: Dep. | D5: 46147
A6: 2E | B6: E | C6: Não | D6: 46147
A7: 8F | B7: F | C7: Dep. | D7: 46148
A8: 8G | B8: G | C8: Sim | D8: 46150
A9: 2H | B9: H | C9: Sim | D9: 46149
A10: 5i | B10: I | C10: Não | D10: 46147
A11: 9J | B11: J | C11: Sim | D11: 46146
A12: 9K | B12: K | C12: Sim | D12: 46146
A13: 5L | B13: L | C13: Não | D13: 46149
... A21: 1R | B21: R | C21: Não | D21: 46150
B22: Retira | C22: Não
A23: 3X | B23: X | C23: Sim | D23: 46149
A26: 3W | B26: W | C26: Sim | D26: 46147

Sheet LAMINADO
B2: Rota Nova | C2: (Vários itens)
B4: M2 | C4: Limite de Produção
C5: 30/abr | D5: 12/mai | E5: 15/mai | F5: 19/mai | G5: 22/mai | H5: 26/mai | I5: Total Geral
B6: Rotas
B7: LMINC06 | F7: 5.1336 | I7: 5.1336
B8: LMINC08 | C8: 3.178 | E8: 4.228 | H8: 16.6759 | I8: 24.0819
B9: LMLT06 | D9: 10.386 | E9: 9.2203 | F9: 3.5356 | H9: 6.8332 | I9: 29.9751
B10: LMLT08 | E10: 2.2176 | F10: 4.2238 | I10: 6.4414
B11: LMREF08 | G11: 3.6568 | I11: 3.6568
B12: Total Geral | C12: 3.178 | D12: 10.386 | E12: 15.6659 | F12: 12.893 | G12: 3.6568 | H12: 23.5091 | I12: 69.2888
